<?xml version="1.0" encoding="UTF-8"?>
<!-- Generated by org.testng.reporters.JUnitReportReporter -->
<testsuite skipped="0" hostname="admin-PC" name="com.TestCase.Login_TestCase_Folder.Login_TestCase" tests="4" failures="2" timestamp="06 Jan 2020 21:46:08 GMT" time="57.639" errors="0">
  <testcase name="Url_Hit" time="25.465" classname="com.TestCase.Login_TestCase_Folder.Login_TestCase"/>
  <testcase name="Without_Password" time="16.153" classname="com.TestCase.Login_TestCase_Folder.Login_TestCase">
    <failure type="java.lang.AssertionError" message="WithOut Password Successfully login...== expected [true] but found [false]">
      <![CDATA[java.lang.AssertionError: WithOut Password Successfully login...== expected [true] but found [false]
at org.testng.Assert.fail(Assert.java:96)
at org.testng.Assert.failNotEquals(Assert.java:776)
at org.testng.Assert.assertTrue(Assert.java:44)
at com.PageObject.Loginpage.LoginPage.UserName(LoginPage.java:45)
at com.TestCase.Login_TestCase_Folder.Login_TestCase.Without_Password(Login_TestCase.java:15)
at sun.reflect.NativeMethodAccessorImpl.invoke0(Native Method)
at sun.reflect.NativeMethodAccessorImpl.invoke(NativeMethodAccessorImpl.java:62)
at sun.reflect.DelegatingMethodAccessorImpl.invoke(DelegatingMethodAccessorImpl.java:43)
at java.lang.reflect.Method.invoke(Method.java:498)
at org.testng.internal.MethodInvocationHelper.invokeMethod(MethodInvocationHelper.java:124)
at org.testng.internal.Invoker.invokeMethod(Invoker.java:583)
at org.testng.internal.Invoker.invokeTestMethod(Invoker.java:719)
at org.testng.internal.Invoker.invokeTestMethods(Invoker.java:989)
at org.testng.internal.TestMethodWorker.invokeTestMethods(TestMethodWorker.java:125)
at org.testng.internal.TestMethodWorker.run(TestMethodWorker.java:109)
at org.testng.TestRunner.privateRun(TestRunner.java:648)
at org.testng.TestRunner.run(TestRunner.java:505)
at org.testng.SuiteRunner.runTest(SuiteRunner.java:455)
at org.testng.SuiteRunner.runSequentially(SuiteRunner.java:450)
at org.testng.SuiteRunner.privateRun(SuiteRunner.java:415)
at org.testng.SuiteRunner.run(SuiteRunner.java:364)
at org.testng.SuiteRunnerWorker.runSuite(SuiteRunnerWorker.java:52)
at org.testng.SuiteRunnerWorker.run(SuiteRunnerWorker.java:84)
at org.testng.TestNG.runSuitesSequentially(TestNG.java:1208)
at org.testng.TestNG.runSuitesLocally(TestNG.java:1137)
at org.testng.TestNG.runSuites(TestNG.java:1049)
at org.testng.TestNG.run(TestNG.java:1017)
at com.intellij.rt.testng.IDEARemoteTestNG.run(IDEARemoteTestNG.java:66)
at com.intellij.rt.testng.RemoteTestNGStarter.main(RemoteTestNGStarter.java:110)
]]>
    </failure>
  </testcase> <!-- Without_Password -->
  <testcase name="Without_UserName" time="9.332" classname="com.TestCase.Login_TestCase_Folder.Login_TestCase">
    <failure type="java.lang.AssertionError" message="WithOut UserName Successfully login...== expected [true] but found [false]">
      <![CDATA[java.lang.AssertionError: WithOut UserName Successfully login...== expected [true] but found [false]
at org.testng.Assert.fail(Assert.java:96)
at org.testng.Assert.failNotEquals(Assert.java:776)
at org.testng.Assert.assertTrue(Assert.java:44)
at com.PageObject.Loginpage.LoginPage.Password_Data(LoginPage.java:70)
at com.TestCase.Login_TestCase_Folder.Login_TestCase.Without_UserName(Login_TestCase.java:19)
at sun.reflect.NativeMethodAccessorImpl.invoke0(Native Method)
at sun.reflect.NativeMethodAccessorImpl.invoke(NativeMethodAccessorImpl.java:62)
at sun.reflect.DelegatingMethodAccessorImpl.invoke(DelegatingMethodAccessorImpl.java:43)
at java.lang.reflect.Method.invoke(Method.java:498)
at org.testng.internal.MethodInvocationHelper.invokeMethod(MethodInvocationHelper.java:124)
at org.testng.internal.Invoker.invokeMethod(Invoker.java:583)
at org.testng.internal.Invoker.invokeTestMethod(Invoker.java:719)
at org.testng.internal.Invoker.invokeTestMethods(Invoker.java:989)
at org.testng.internal.TestMethodWorker.invokeTestMethods(TestMethodWorker.java:125)
at org.testng.internal.TestMethodWorker.run(TestMethodWorker.java:109)
at org.testng.TestRunner.privateRun(TestRunner.java:648)
at org.testng.TestRunner.run(TestRunner.java:505)
at org.testng.SuiteRunner.runTest(SuiteRunner.java:455)
at org.testng.SuiteRunner.runSequentially(SuiteRunner.java:450)
at org.testng.SuiteRunner.privateRun(SuiteRunner.java:415)
at org.testng.SuiteRunner.run(SuiteRunner.java:364)
at org.testng.SuiteRunnerWorker.runSuite(SuiteRunnerWorker.java:52)
at org.testng.SuiteRunnerWorker.run(SuiteRunnerWorker.java:84)
at org.testng.TestNG.runSuitesSequentially(TestNG.java:1208)
at org.testng.TestNG.runSuitesLocally(TestNG.java:1137)
at org.testng.TestNG.runSuites(TestNG.java:1049)
at org.testng.TestNG.run(TestNG.java:1017)
at com.intellij.rt.testng.IDEARemoteTestNG.run(IDEARemoteTestNG.java:66)
at com.intellij.rt.testng.RemoteTestNGStarter.main(RemoteTestNGStarter.java:110)
]]>
    </failure>
  </testcase> <!-- Without_UserName -->
  <testcase name="With_Username_Password" time="6.689" classname="com.TestCase.Login_TestCase_Folder.Login_TestCase"/>
</testsuite> <!-- com.TestCase.Login_TestCase_Folder.Login_TestCase -->
